INFO: Starting training:
        Image:           data/1_input_scratch/JPEGImages
        Label:           data/1_input_scratch/SegmentationClass
        Checkpoints:     data/14_output_checkpoint_unet
        Epochs:          5
        Batch size:      1
        Learning rate:   1e-05
        Training size:   450
        Validation size: 50
        Checkpoints:     True
        Device:          cuda
        Images scaling:  0.5
        Mixed Precision: False
Epoch 1/5:   0%|          | 0/450 [00:01<?, ?img/s]
Traceback (most recent call last):
  File "unet/train.py", line 196, in <module>
    train_net(net=net,
  File "unet/train.py", line 86, in train_net
    for batch in train_loader:
  File "C:\Users\anindita\anaconda3\envs\envTorch1\lib\site-packages\torch\utils\data\dataloader.py", line 530, in __next__
    data = self._next_data()
  File "C:\Users\anindita\anaconda3\envs\envTorch1\lib\site-packages\torch\utils\data\dataloader.py", line 1224, in _next_data
    return self._process_data(data)
  File "C:\Users\anindita\anaconda3\envs\envTorch1\lib\site-packages\torch\utils\data\dataloader.py", line 1250, in _process_data
    data.reraise()
  File "C:\Users\anindita\anaconda3\envs\envTorch1\lib\site-packages\torch\_utils.py", line 457, in reraise
    raise exception
AssertionError: Caught AssertionError in DataLoader worker process 0.
Original Traceback (most recent call last):
  File "C:\Users\anindita\anaconda3\envs\envTorch1\lib\site-packages\torch\utils\data\_utils\worker.py", line 287, in _worker_loop
    data = fetcher.fetch(index)
  File "C:\Users\anindita\anaconda3\envs\envTorch1\lib\site-packages\torch\utils\data\_utils\fetch.py", line 49, in fetch
    data = [self.dataset[idx] for idx in possibly_batched_index]
  File "C:\Users\anindita\anaconda3\envs\envTorch1\lib\site-packages\torch\utils\data\_utils\fetch.py", line 49, in <listcomp>
    data = [self.dataset[idx] for idx in possibly_batched_index]
  File "C:\Users\anindita\anaconda3\envs\envTorch1\lib\site-packages\torch\utils\data\dataset.py", line 471, in __getitem__
    return self.dataset[self.indices[idx]]
  File "D:\Dropbox\PhD\python\GAN_SCRATCH_1\unet\utils\data_loading.py", line 62, in __getitem__
    assert len(mask_file) == 1, f'Either no mask or multiple masks found for the ID {name}: {mask_file}'
AssertionError: Either no mask or multiple masks found for the ID 201022_2_384: []